<?xml version="1.0"?>
<robot xmlns:xacro="http://www.ros.org/wiki/xacro">
  <xacro:property name="jaka_a12_mesh_path" value="package://jaka_description/meshes/jaka_a12_meshes"/>

  <xacro:macro name="jaka_a12_prefixed" params="prefix parent:=world base_xyz:='0 0 0' base_rpy:='0 0 0' include_inertial:=false">
    <link name="${prefix}base_link">
      <xacro:if value="${include_inertial}">
        <inertial>
          <origin xyz="0.00016274 2.3475E-05 0.017516" rpy="0 0 0"/>
          <mass value="0.84938"/>
          <inertia
            ixx="0.0015415"
            ixy="5.5705E-08"
            ixz="-1.6043E-07"
            iyy="0.0018861"
            iyz="2.6186E-07"
            izz="0.0032224"/>
        </inertial>
      </xacro:if>
      <visual>
        <origin xyz="0 0 0" rpy="0 0 0"/>
        <geometry>
          <mesh filename="${jaka_a12_mesh_path}/base_link.STL"/>
        </geometry>
        <material name="${prefix}base_material">
          <color rgba="0.79216 0.81961 0.93333 1"/>
        </material>
      </visual>
      <collision>
        <origin xyz="0 0 0" rpy="0 0 0"/>
        <geometry>
          <mesh filename="${jaka_a12_mesh_path}/base_link.STL"/>
        </geometry>
      </collision>
    </link>

    <joint name="${prefix}fixed" type="fixed">
      <origin xyz="${base_xyz}" rpy="${base_rpy}"/>
      <parent link="${parent}"/>
      <child link="${prefix}base_link"/>
    </joint>

    <link name="${prefix}J1">
      <xacro:if value="${include_inertial}">
        <inertial>
          <origin xyz="6.0416E-08 -0.0029272 -0.004247" rpy="0 0 0"/>
          <mass value="3.7579"/>
          <inertia
            ixx="0.01765"
            ixy="-2.5806E-07"
            ixz="-1.3081E-07"
            iyy="0.017355"
            iyz="3.4234E-05"
            izz="0.011502"/>
        </inertial>
      </xacro:if>
      <visual>
        <origin xyz="0 0 0" rpy="0 0 0"/>
        <geometry>
          <mesh filename="${jaka_a12_mesh_path}/J1.STL"/>
        </geometry>
        <material name="${prefix}j1_material">
          <color rgba="0.79216 0.81961 0.93333 1"/>
        </material>
      </visual>
      <collision>
        <origin xyz="0 0 0" rpy="0 0 0"/>
        <geometry>
          <mesh filename="${jaka_a12_mesh_path}/J1.STL"/>
        </geometry>
      </collision>
    </link>

    <joint name="${prefix}joint_1" type="revolute">
      <origin xyz="9.3823E-05 0 0.14265" rpy="0 0 0"/>
      <parent link="${prefix}base_link"/>
      <child link="${prefix}J1"/>
      <axis xyz="0 0 1"/>
      <limit lower="-6.28" upper="6.28" effort="2000" velocity="2.62"/>
    </joint>

    <link name="${prefix}J2">
      <xacro:if value="${include_inertial}">
        <inertial>
          <origin xyz="0.32342 7.7419E-08 0.1801" rpy="0 0 0"/>
          <mass value="13.37"/>
          <inertia
            ixx="0.038258"
            ixy="3.482E-08"
            ixz="-0.0030725"
            iyy="1.0882"
            iyz="5.5423E-08"
            izz="1.0803"/>
        </inertial>
      </xacro:if>
      <visual>
        <origin xyz="0 0 0" rpy="0 0 0"/>
        <geometry>
          <mesh filename="${jaka_a12_mesh_path}/J2.STL"/>
        </geometry>
        <material name="${prefix}j2_material">
          <color rgba="0.86667 0.86667 0.8902 1"/>
        </material>
      </visual>
      <collision>
        <origin xyz="0 0 0" rpy="0 0 0"/>
        <geometry>
          <mesh filename="${jaka_a12_mesh_path}/J2.STL"/>
        </geometry>
      </collision>
    </link>

    <joint name="${prefix}joint_2" type="revolute">
      <origin xyz="0 0 0" rpy="1.5708 0 0"/>
      <parent link="${prefix}J1"/>
      <child link="${prefix}J2"/>
      <axis xyz="0 0 1"/>
      <limit lower="-6.28" upper="6.28" effort="8000" velocity="2.62"/>
    </joint>

    <link name="${prefix}J3">
      <xacro:if value="${include_inertial}">
        <inertial>
          <origin xyz="-4.2655E-07 -0.0024273 0.002914" rpy="0 0 0"/>
          <mass value="1.9435"/>
          <inertia
            ixx="0.0057394"
            ixy="3.386E-10"
            ixz="7.7883E-08"
            iyy="0.0038913"
            iyz="3.3725E-06"
            izz="0.0056521"/>
        </inertial>
      </xacro:if>
      <visual>
        <origin xyz="0 0 0" rpy="0 0 0"/>
        <geometry>
          <mesh filename="${jaka_a12_mesh_path}/J3.STL"/>
        </geometry>
        <material name="${prefix}j3_material">
          <color rgba="0.86667 0.86667 0.8902 1"/>
        </material>
      </visual>
      <collision>
        <origin xyz="0 0 0" rpy="0 0 0"/>
        <geometry>
          <mesh filename="${jaka_a12_mesh_path}/J3.STL"/>
        </geometry>
      </collision>
    </link>

    <joint name="${prefix}joint_3" type="revolute">
      <origin xyz="0.77 0 0.0375" rpy="0 0 1.5708"/>
      <parent link="${prefix}J2"/>
      <child link="${prefix}J3"/>
      <axis xyz="0 0 1"/>
      <limit lower="-6.28" upper="6.28" effort="8000" velocity="3.67"/>
    </joint>

    <link name="${prefix}J4">
      <xacro:if value="${include_inertial}">
        <inertial>
          <origin xyz="3.1406E-08 -0.00097336 -0.21333" rpy="0 0 0"/>
          <mass value="3.903"/>
          <inertia
            ixx="0.10135"
            ixy="4.9565E-08"
            ixz="-9.9161E-09"
            iyy="0.10077"
            iyz="0.00080984"
            izz="0.0051085"/>
        </inertial>
      </xacro:if>
      <visual>
        <origin xyz="0 0 0" rpy="0 0 0"/>
        <geometry>
          <mesh filename="${jaka_a12_mesh_path}/J4.STL"/>
        </geometry>
        <material name="${prefix}j4_material">
          <color rgba="0.79216 0.81961 0.93333 1"/>
        </material>
      </visual>
      <collision>
        <origin xyz="0 0 0" rpy="0 0 0"/>
        <geometry>
          <mesh filename="${jaka_a12_mesh_path}/J4.STL"/>
        </geometry>
      </collision>
    </link>

    <joint name="${prefix}joint_4" type="revolute">
      <origin xyz="0 -0.5515 0" rpy="-1.5708 0 -3.1416"/>
      <parent link="${prefix}J3"/>
      <child link="${prefix}J4"/>
      <axis xyz="0 0 1"/>
      <limit lower="-6.28" upper="6.28" effort="2000" velocity="3.67"/>
    </joint>

    <link name="${prefix}J5">
      <xacro:if value="${include_inertial}">
        <inertial>
          <origin xyz="1.1338E-07 0.0049095 -0.0024985" rpy="0 0 0"/>
          <mass value="1.0253"/>
          <inertia
            ixx="0.0022543"
            ixy="1.8791E-09"
            ixz="1.7943E-08"
            iyy="0.0011832"
            iyz="-1.3434E-05"
            izz="0.0022184"/>
        </inertial>
      </xacro:if>
      <visual>
        <origin xyz="0 0 0" rpy="0 0 0"/>
        <geometry>
          <mesh filename="${jaka_a12_mesh_path}/J5.STL"/>
        </geometry>
        <material name="${prefix}j5_material">
          <color rgba="0.86667 0.86667 0.8902 1"/>
        </material>
      </visual>
      <collision>
        <origin xyz="0 0 0" rpy="0 0 0"/>
        <geometry>
          <mesh filename="${jaka_a12_mesh_path}/J5.STL"/>
        </geometry>
      </collision>
    </link>

    <joint name="${prefix}joint_5" type="revolute">
      <origin xyz="0 -0.115 0" rpy="-1.5708 -1.5708 3.1416"/>
      <parent link="${prefix}J4"/>
      <child link="${prefix}J5"/>
      <axis xyz="0 0 1"/>
      <limit lower="-6.28" upper="6.28" effort="3000" velocity="3.67"/>
    </joint>

    <link name="${prefix}J6">
      <xacro:if value="${include_inertial}">
        <inertial>
          <origin xyz="-6.1189E-05 -5.6233E-05 -0.020571" rpy="0 0 0"/>
          <mass value="0.2135"/>
          <inertia
            ixx="0.00012541"
            ixy="4.199E-07"
            ixz="-2.6224E-08"
            iyy="0.00012595"
            iyz="-1.6646E-07"
            izz="0.00021163"/>
        </inertial>
      </xacro:if>
      <visual>
        <origin xyz="0 0 0" rpy="0 0 0"/>
        <geometry>
          <mesh filename="${jaka_a12_mesh_path}/J6.STL"/>
        </geometry>
        <material name="${prefix}j6_material">
          <color rgba="0.79216 0.81961 0.93333 1"/>
        </material>
      </visual>
      <collision>
        <origin xyz="0 0 0" rpy="0 0 0"/>
        <geometry>
          <mesh filename="${jaka_a12_mesh_path}/J6.STL"/>
        </geometry>
      </collision>
    </link>

    <joint name="${prefix}joint_6" type="revolute">
      <origin xyz="0 -0.1035 0" rpy="1.5708 0 0"/>
      <parent link="${prefix}J5"/>
      <child link="${prefix}J6"/>
      <axis xyz="0 0 1"/>
      <limit lower="-6.28" upper="6.28" effort="1000" velocity="3.67"/>
    </joint>

    <transmission name="${prefix}trans_joint_1">
      <type>transmission_interface/SimpleTransmission</type>
      <joint name="${prefix}joint_1">
        <hardwareInterface>hardware_interface/PositionJointInterface</hardwareInterface>
      </joint>
      <actuator name="${prefix}joint_1_motor">
        <hardwareInterface>hardware_interface/PositionJointInterface</hardwareInterface>
        <mechanicalReduction>1</mechanicalReduction>
      </actuator>
    </transmission>
    <transmission name="${prefix}trans_joint_2">
      <type>transmission_interface/SimpleTransmission</type>
      <joint name="${prefix}joint_2">
        <hardwareInterface>hardware_interface/PositionJointInterface</hardwareInterface>
      </joint>
      <actuator name="${prefix}joint_2_motor">
        <hardwareInterface>hardware_interface/PositionJointInterface</hardwareInterface>
        <mechanicalReduction>1</mechanicalReduction>
      </actuator>
    </transmission>
    <transmission name="${prefix}trans_joint_3">
      <type>transmission_interface/SimpleTransmission</type>
      <joint name="${prefix}joint_3">
        <hardwareInterface>hardware_interface/PositionJointInterface</hardwareInterface>
      </joint>
      <actuator name="${prefix}joint_3_motor">
        <hardwareInterface>hardware_interface/PositionJointInterface</hardwareInterface>
        <mechanicalReduction>1</mechanicalReduction>
      </actuator>
    </transmission>
    <transmission name="${prefix}trans_joint_4">
      <type>transmission_interface/SimpleTransmission</type>
      <joint name="${prefix}joint_4">
        <hardwareInterface>hardware_interface/PositionJointInterface</hardwareInterface>
      </joint>
      <actuator name="${prefix}joint_4_motor">
        <hardwareInterface>hardware_interface/PositionJointInterface</hardwareInterface>
        <mechanicalReduction>1</mechanicalReduction>
      </actuator>
    </transmission>
    <transmission name="${prefix}trans_joint_5">
      <type>transmission_interface/SimpleTransmission</type>
      <joint name="${prefix}joint_5">
        <hardwareInterface>hardware_interface/PositionJointInterface</hardwareInterface>
      </joint>
      <actuator name="${prefix}joint_5_motor">
        <hardwareInterface>hardware_interface/PositionJointInterface</hardwareInterface>
        <mechanicalReduction>1</mechanicalReduction>
      </actuator>
    </transmission>
    <transmission name="${prefix}trans_joint_6">
      <type>transmission_interface/SimpleTransmission</type>
      <joint name="${prefix}joint_6">
        <hardwareInterface>hardware_interface/PositionJointInterface</hardwareInterface>
      </joint>
      <actuator name="${prefix}joint_6_motor">
        <hardwareInterface>hardware_interface/PositionJointInterface</hardwareInterface>
        <mechanicalReduction>1</mechanicalReduction>
      </actuator>
    </transmission>
  </xacro:macro>
</robot>
